

---------- Outline Creation Feedback Conversation Starting ----------


basic_chat: Admin -> Strategy_Planner
Admin (to Strategy_Planner):


    Create an outline for a podcast that gives an introduction around the discography of Fleetwood Mac.

    FRAMEWORK OF PODCAST
    Their life should be divided up in different era's based upon the themes and events in their life. The music in the podcast should contain some of their big hits, but also play some lesser know gems. You can always mention hits, without playing them. In more prolific era's of the artists career, you can mention more tracks. The era's should be more of a guideline and are not explicitly mentioned in the podcast.
    In total the podcast should contain about 10 tracks but it may vary. 
    In total the speaking time should be around 15 minutes.
    

--------------------------------------------------------------------------------
Traceback (most recent call last):
  File "/Users/kbverlaan/Library/Caches/pypoetry/virtualenvs/autogen-podcast-AeYdH5Jj-py3.10/lib/python3.10/site-packages/urllib3/connectionpool.py", line 537, in _make_request
    response = conn.getresponse()
  File "/Users/kbverlaan/Library/Caches/pypoetry/virtualenvs/autogen-podcast-AeYdH5Jj-py3.10/lib/python3.10/site-packages/urllib3/connection.py", line 461, in getresponse
    httplib_response = super().getresponse()
  File "/Users/kbverlaan/miniforge3/lib/python3.10/http/client.py", line 1374, in getresponse
    response.begin()
  File "/Users/kbverlaan/miniforge3/lib/python3.10/http/client.py", line 318, in begin
    version, status, reason = self._read_status()
  File "/Users/kbverlaan/miniforge3/lib/python3.10/http/client.py", line 279, in _read_status
    line = str(self.fp.readline(_MAXLINE + 1), "iso-8859-1")
  File "/Users/kbverlaan/miniforge3/lib/python3.10/socket.py", line 705, in readinto
    return self._sock.recv_into(b)
  File "/Users/kbverlaan/miniforge3/lib/python3.10/ssl.py", line 1274, in recv_into
    return self.read(nbytes, buffer)
  File "/Users/kbverlaan/miniforge3/lib/python3.10/ssl.py", line 1130, in read
    return self._sslobj.read(len, buffer)
TimeoutError: The read operation timed out

The above exception was the direct cause of the following exception:

Traceback (most recent call last):
  File "/Users/kbverlaan/Library/Caches/pypoetry/virtualenvs/autogen-podcast-AeYdH5Jj-py3.10/lib/python3.10/site-packages/requests/adapters.py", line 486, in send
    resp = conn.urlopen(
  File "/Users/kbverlaan/Library/Caches/pypoetry/virtualenvs/autogen-podcast-AeYdH5Jj-py3.10/lib/python3.10/site-packages/urllib3/connectionpool.py", line 845, in urlopen
    retries = retries.increment(
  File "/Users/kbverlaan/Library/Caches/pypoetry/virtualenvs/autogen-podcast-AeYdH5Jj-py3.10/lib/python3.10/site-packages/urllib3/util/retry.py", line 470, in increment
    raise reraise(type(error), error, _stacktrace)
  File "/Users/kbverlaan/Library/Caches/pypoetry/virtualenvs/autogen-podcast-AeYdH5Jj-py3.10/lib/python3.10/site-packages/urllib3/util/util.py", line 39, in reraise
    raise value
  File "/Users/kbverlaan/Library/Caches/pypoetry/virtualenvs/autogen-podcast-AeYdH5Jj-py3.10/lib/python3.10/site-packages/urllib3/connectionpool.py", line 791, in urlopen
    response = self._make_request(
  File "/Users/kbverlaan/Library/Caches/pypoetry/virtualenvs/autogen-podcast-AeYdH5Jj-py3.10/lib/python3.10/site-packages/urllib3/connectionpool.py", line 539, in _make_request
    self._raise_timeout(err=e, url=url, timeout_value=read_timeout)
  File "/Users/kbverlaan/Library/Caches/pypoetry/virtualenvs/autogen-podcast-AeYdH5Jj-py3.10/lib/python3.10/site-packages/urllib3/connectionpool.py", line 371, in _raise_timeout
    raise ReadTimeoutError(
urllib3.exceptions.ReadTimeoutError: HTTPSConnectionPool(host='api.openai.com', port=443): Read timed out. (read timeout=120)

During handling of the above exception, another exception occurred:

Traceback (most recent call last):
  File "/Users/kbverlaan/Library/Caches/pypoetry/virtualenvs/autogen-podcast-AeYdH5Jj-py3.10/lib/python3.10/site-packages/openai/api_requestor.py", line 606, in request_raw
    result = _thread_context.session.request(
  File "/Users/kbverlaan/Library/Caches/pypoetry/virtualenvs/autogen-podcast-AeYdH5Jj-py3.10/lib/python3.10/site-packages/requests/sessions.py", line 589, in request
    resp = self.send(prep, **send_kwargs)
  File "/Users/kbverlaan/Library/Caches/pypoetry/virtualenvs/autogen-podcast-AeYdH5Jj-py3.10/lib/python3.10/site-packages/requests/sessions.py", line 703, in send
    r = adapter.send(request, **kwargs)
  File "/Users/kbverlaan/Library/Caches/pypoetry/virtualenvs/autogen-podcast-AeYdH5Jj-py3.10/lib/python3.10/site-packages/requests/adapters.py", line 532, in send
    raise ReadTimeout(e, request=request)
requests.exceptions.ReadTimeout: HTTPSConnectionPool(host='api.openai.com', port=443): Read timed out. (read timeout=120)

The above exception was the direct cause of the following exception:

Traceback (most recent call last):
  File "<string>", line 1, in <module>
  File "/Users/kbverlaan/GitProjects/autogen-podcast/autogen_podcast/main.py", line 34, in main
    success, strategy_messages = outline_creation_orchestrator.feedback_conversation(prompt)
  File "/Users/kbverlaan/GitProjects/autogen-podcast/autogen_podcast/modules/orchestrator.py", line 209, in feedback_conversation
    self.basic_chat(agent_a, agent_b, self.latest_message)
  File "/Users/kbverlaan/GitProjects/autogen-podcast/autogen_podcast/modules/orchestrator.py", line 79, in basic_chat
    reply = agent_b.generate_reply(sender=agent_a)
  File "/Users/kbverlaan/Library/Caches/pypoetry/virtualenvs/autogen-podcast-AeYdH5Jj-py3.10/lib/python3.10/site-packages/autogen/agentchat/conversable_agent.py", line 781, in generate_reply
    final, reply = reply_func(self, messages=messages, sender=sender, config=reply_func_tuple["config"])
  File "/Users/kbverlaan/Library/Caches/pypoetry/virtualenvs/autogen-podcast-AeYdH5Jj-py3.10/lib/python3.10/site-packages/autogen/agentchat/conversable_agent.py", line 606, in generate_oai_reply
    response = oai.ChatCompletion.create(
  File "/Users/kbverlaan/Library/Caches/pypoetry/virtualenvs/autogen-podcast-AeYdH5Jj-py3.10/lib/python3.10/site-packages/autogen/oai/completion.py", line 803, in create
    response = cls.create(
  File "/Users/kbverlaan/Library/Caches/pypoetry/virtualenvs/autogen-podcast-AeYdH5Jj-py3.10/lib/python3.10/site-packages/autogen/oai/completion.py", line 834, in create
    return cls._get_response(params, raise_on_ratelimit_or_timeout=raise_on_ratelimit_or_timeout)
  File "/Users/kbverlaan/Library/Caches/pypoetry/virtualenvs/autogen-podcast-AeYdH5Jj-py3.10/lib/python3.10/site-packages/autogen/oai/completion.py", line 222, in _get_response
    response = openai_completion.create(**config)
  File "/Users/kbverlaan/Library/Caches/pypoetry/virtualenvs/autogen-podcast-AeYdH5Jj-py3.10/lib/python3.10/site-packages/openai/api_resources/chat_completion.py", line 25, in create
    return super().create(*args, **kwargs)
  File "/Users/kbverlaan/Library/Caches/pypoetry/virtualenvs/autogen-podcast-AeYdH5Jj-py3.10/lib/python3.10/site-packages/openai/api_resources/abstract/engine_api_resource.py", line 155, in create
    response, _, api_key = requestor.request(
  File "/Users/kbverlaan/Library/Caches/pypoetry/virtualenvs/autogen-podcast-AeYdH5Jj-py3.10/lib/python3.10/site-packages/openai/api_requestor.py", line 289, in request
    result = self.request_raw(
  File "/Users/kbverlaan/Library/Caches/pypoetry/virtualenvs/autogen-podcast-AeYdH5Jj-py3.10/lib/python3.10/site-packages/openai/api_requestor.py", line 617, in request_raw
    raise error.Timeout("Request timed out: {}".format(e)) from e
openai.error.Timeout: Request timed out: HTTPSConnectionPool(host='api.openai.com', port=443): Read timed out. (read timeout=120)
